Workbook

Sheet 702
A2: Application and Certificate for Payment
A3: OWNER: | I3: PROJECT: | T3: APPLICATION NO: | AC3: Distribution to:
AA4: OWNER | AB4: :
T5: PERIOD TO: | AA5: ARCHITECT | AB5: :
T6: SUBCONTRACT FOR: | AA6: CONTRACTOR | AB6: :
A7: CONTRACTOR: | I7: VIA ARCHITECT: | T7: SUBCONTRACT DATE: | AA7: FIELD | AB7: :
T8: PROJECT NOS: | AA8: Bank | AB8: :
A11: CONTRACTOR: | AA11: FIELD | AB11: :
AA12: Bank | AB12: :
A15: SUBCONTRACTOR'S APPLCIATION FOR PAYMENT
A16: Application is made for payment, as shown below, in connection with the Subcontract.
A17: Continuation Sheet, AIA Document G703, is attached.
A18: 1. ORIGINAL SUBCONTRACT SUM | J18: ='703'!C66 -> 0
A19: 2. NET CHANGE BY CHANGE ORDERS | J19: 0 | O19: CONTRACTOR:
A20: 3. SUBCONTRACT SUM TO DATE (Line 1+2) | J20: =SUM(J18:K19) -> 0 | O20: By: | W20: Date:
A21: 4. TOTAL COMPLETED & STORED TO DATED (Column G on G703) | J21: ='703'!G66 -> 0 | O21: State of:
A22: 5. RETAINAGE | O22: County of:
A23: a. | C23: % of Completed Work | O23: Subscribed and sworn to before
B24: (Column D + E on G703: | G24: ) | H24: = | O24: me this | T24: day of
A25: b. | C25: % of Stored Material
B26: (Column F on G703: | G26: ) | H26: = | I26: =F26*B25% -> 0 | O26: Notary Public:
A27: Total Retainage (Lines 5a + 5b or Total in Column I of G703) | J27: ='703'!J66 -> 0 | O27: My Commission Expires:
O28: ARCHITECT'S CERTIFICATE FOR PAYMENT
A29: 6. TOTAL EARNED LESS RETAINAGE | J29: =J21-J27 -> 0
B30: (Line 4 Less Line 5 Total)
A31: 7. LESS PREVIOUS CERTIFICATES FOR PAYMENT
B32: (Line 6 from prior Certificate)
A33: 8. CURRENT PAYMENT DUE | J33: =J29-J31 -> 0
A34: 9. BALANCE TO FINISH, INCLUDING RETAINAGE
B35: (Line 3 less Line 6) | I35: =J20-J29 -> 0 | O35: AMOUNT CERTIFIED | U35: $
A38: CHANGE ORDER SUMMARY | I38: ADDITIONS | J38: DEDUCTIONS | O38: ARCHITECT:
A39: Total changes approved in previous months by Owner | O39: By: | Y39: Date:
A40: Total approved this Month
A41: TOTALS | I41: =SUM(I39:I40) -> 0 | J41: =SUM(J39:K40) -> 0

Sheet 703
A1: Continuation Sheet
G3: APPLICATION NO:
G4: APPLICATION DATE:
G5: PERIOD TO:
G6: ARCHITECT'S PROJECT NO:
A7: A | B7: B | C7: C | D7: D | E7: E | F7: F | G7: G | I7: H | J7: I
A8: ITEM NO. | B8: DESCRIPTION OF WORK | C8: SCHEDULED VALUE | D8: WORK COMPLETED | F8: MATERIALS PRESENTLY STORED (NOT IN D OR E) | G8: TOTAL COMPLETED AND STORED TO DATE (D+E+F) | H8: % (G÷C) | I8: BALANCE TO FINISH (C-G) | J8: RETAINAGE (IF VARIABLE RATE)
D9: FROM PREVIOUS APPLICATION (D+E) | E9: THIS PERIOD
B10: CONSTRUCTION HARD COSTS
A12: 1 | B12: General Requirements | C12: 0 | D12: 0 | E12: 0 | G12: =SUM(D12:F12) -> 0 | H12: =IFERROR(G12/C12,0) -> 0 | I12: =C12-G12 -> 0 | J12: =SUMIF(Detail!$E$4:$E$91,A12,Detail!$H$4:$H$91) -> 0
A13: 2 | B13: Existing Conditions | C13: 0 | D13: 0 | E13: =SUMIFS(Detail!$G$3:$G$92,Detail!$D$3:$D$92,"01",Detail!$E$3:$E$92,'703'!A13) -> 0 | G13: =SUM(D13:F13) -> 0 | H13: =IFERROR(G13/C13,0) -> 0 | I13: =C13-G13 -> 0 | J13: =SUMIF(Detail!$E$4:$E$91,A13,Detail!$H$4:$H$91) -> 0
A14: 3 | B14: Concrete | C14: 0 | D14: 0 | E14: =SUMIFS(Detail!$G$3:$G$92,Detail!$D$3:$D$92,"01",Detail!$E$3:$E$92,'703'!A14) -> 0 | G14: =SUM(D14:F14) -> 0 | H14: =IFERROR(G14/C14,0) -> 0 | I14: =C14-G14 -> 0 | J14: =SUMIF(Detail!$E$4:$E$91,A14,Detail!$H$4:$H$91) -> 0
A15: 4 | B15: Masonry | C15: 0 | D15: 0 | E15: =SUMIFS(Detail!$G$3:$G$92,Detail!$D$3:$D$92,"01",Detail!$E$3:$E$92,'703'!A15) -> 0 | G15: =SUM(D15:F15) -> 0 | H15: =IFERROR(G15/C15,0) -> 0 | I15: =C15-G15 -> 0 | J15: =SUMIF(Detail!$E$4:$E$91,A15,Detail!$H$4:$H$91) -> 0
A16: 5 | B16: Metals | C16: 0 | D16: 0 | E16: =SUMIFS(Detail!$G$3:$G$92,Detail!$D$3:$D$92,"01",Detail!$E$3:$E$92,'703'!A16) -> 0 | G16: =SUM(D16:F16) -> 0 | H16: =IFERROR(G16/C16,0) -> 0 | I16: =C16-G16 -> 0 | J16: =SUMIF(Detail!$E$4:$E$91,A16,Detail!$H$4:$H$91) -> 0
A17: 6 | B17: Woods, Plastics & Composits | C17: 0 | D17: 0 | E17: =SUMIFS(Detail!$G$3:$G$92,Detail!$D$3:$D$92,"01",Detail!$E$3:$E$92,'703'!A17) -> 0 | G17: =SUM(D17:F17) -> 0 | H17: =IFERROR(G17/C17,0) -> 0 | I17: =C17-G17 -> 0 | J17: =SUMIF(Detail!$E$4:$E$91,A17,Detail!$H$4:$H$91) -> 0
A18: 7 | B18: Thermal & Moisture Protection | C18: 0 | D18: 0 | E18: =SUMIFS(Detail!$G$3:$G$92,Detail!$D$3:$D$92,"01",Detail!$E$3:$E$92,'703'!A18) -> 0 | G18: =SUM(D18:F18) -> 0 | H18: =IFERROR(G18/C18,0) -> 0 | I18: =C18-G18 -> 0 | J18: =SUMIF(Detail!$E$4:$E$91,A18,Detail!$H$4:$H$91) -> 0
A19: 8 | B19: Openings | C19: 0 | D19: 0 | E19: =SUMIFS(Detail!$G$3:$G$92,Detail!$D$3:$D$92,"01",Detail!$E$3:$E$92,'703'!A19) -> 0 | G19: =SUM(D19:F19) -> 0 | H19: =IFERROR(G19/C19,0) -> 0 | I19: =C19-G19 -> 0 | J19: =SUMIF(Detail!$E$4:$E$91,A19,Detail!$H$4:$H$91) -> 0
A20: 9 | B20: Finishes | C20: 0 | D20: 0 | E20: =SUMIFS(Detail!$G$3:$G$92,Detail!$D$3:$D$92,"01",Detail!$E$3:$E$92,'703'!A20) -> 0 | G20: =SUM(D20:F20) -> 0 | H20: =IFERROR(G20/C20,0) -> 0 | I20: =C20-G20 -> 0 | J20: =SUMIF(Detail!$E$4:$E$91,A20,Detail!$H$4:$H$91) -> 0
A21: 10 | B21: Specialties | C21: 0 | D21: 0 | E21: =SUMIFS(Detail!$G$3:$G$92,Detail!$D$3:$D$92,"01",Detail!$E$3:$E$92,'703'!A21) -> 0 | G21: =SUM(D21:F21) -> 0 | H21: =IFERROR(G21/C21,0) -> 0 | I21: =C21-G21 -> 0 | J21: =SUMIF(Detail!$E$4:$E$91,A21,Detail!$H$4:$H$91) -> 0
A22: 11 | B22: Equipment | C22: 0 | D22: 0 | E22: =SUMIFS(Detail!$G$3:$G$92,Detail!$D$3:$D$92,"01",Detail!$E$3:$E$92,'703'!A22) -> 0 | G22: =SUM(D22:F22) -> 0 | H22: =IFERROR(G22/C22,0) -> 0 | I22: =C22-G22 -> 0 | J22: =SUMIF(Detail!$E$4:$E$91,A22,Detail!$H$4:$H$91) -> 0
A23: 12 | B23: Furnishings | C23: 0 | D23: 0 | E23: =SUMIFS(Detail!$G$3:$G$92,Detail!$D$3:$D$92,"01",Detail!$E$3:$E$92,'703'!A23) -> 0 | G23: =SUM(D23:F23) -> 0 | H23: =IFERROR(G23/C23,0) -> 0 | I23: =C23-G23 -> 0 | J23: =SUMIF(Detail!$E$4:$E$91,A23,Detail!$H$4:$H$91) -> 0
A24: 13 | B24: Special Construction | C24: 0 | D24: 0 | E24: =SUMIFS(Detail!$G$3:$G$92,Detail!$D$3:$D$92,"01",Detail!$E$3:$E$92,'703'!A24) -> 0 | G24: =SUM(D24:F24) -> 0 | H24: =IFERROR(G24/C24,0) -> 0 | I24: =C24-G24 -> 0 | J24: =SUMIF(Detail!$E$4:$E$91,A24,Detail!$H$4:$H$91) -> 0
A25: 14 | B25: Conveying Equipment | C25: 0 | D25: 0 | E25: 0 | G25: =SUM(D25:F25) -> 0 | H25: =IFERROR(G25/C25,0) -> 0 | I25: =C25-G25 -> 0 | J25: =SUMIF(Detail!$E$4:$E$91,A25,Detail!$H$4:$H$91) -> 0
A26: 21 | B26: Fire Suppression | C26: 0 | D26: 0 | E26: =SUMIFS(Detail!$G$3:$G$92,Detail!$D$3:$D$92,"01",Detail!$E$3:$E$92,'703'!A26) -> 0 | G26: =SUM(D26:F26) -> 0 | H26: =IFERROR(G26/C26,0) -> 0 | I26: =C26-G26 -> 0 | J26: =SUMIF(Detail!$E$4:$E$91,A26,Detail!$H$4:$H$91) -> 0
A27: 22 | B27: Plumbing | C27: 0 | D27: 0 | E27: =SUMIFS(Detail!$G$3:$G$92,Detail!$D$3:$D$92,"01",Detail!$E$3:$E$92,'703'!A27) -> 0 | G27: =SUM(D27:F27) -> 0 | H27: =IFERROR(G27/C27,0) -> 0 | I27: =C27-G27 -> 0 | J27: =SUMIF(Detail!$E$4:$E$91,A27,Detail!$H$4:$H$91) -> 0
A28: 23 | B28: HVAC | C28: 0 | D28: 0 | E28: =SUMIFS(Detail!$G$3:$G$92,Detail!$D$3:$D$92,"01",Detail!$E$3:$E$92,'703'!A28) -> 0 | G28: =SUM(D28:F28) -> 0 | H28: =IFERROR(G28/C28,0) -> 0 | I28: =C28-G28 -> 0 | J28: =SUMIF(Detail!$E$4:$E$91,A28,Detail!$H$4:$H$91) -> 0
A29: 26 | B29: Electrical | C29: 0 | D29: 0 | E29: =SUMIFS(Detail!$G$3:$G$92,Detail!$D$3:$D$92,"01",Detail!$E$3:$E$92,'703'!A29) -> 0 | G29: =SUM(D29:F29) -> 0 | H29: =IFERROR(G29/C29,0) -> 0 | I29: =C29-G29 -> 0 | J29: =SUMIF(Detail!$E$4:$E$91,A29,Detail!$H$4:$H$91) -> 0
A30: 28 | B30: Electronic Safety & Security | C30: 0 | D30: 0 | E30: =SUMIFS(Detail!$G$3:$G$92,Detail!$D$3:$D$92,"01",Detail!$E$3:$E$92,'703'!A30) -> 0 | G30: =SUM(D30:F30) -> 0 | H30: =IFERROR(G30/C30,0) -> 0 | I30: =C30-G30 -> 0 | J30: =SUMIF(Detail!$E$4:$E$91,A30,Detail!$H$4:$H$91) -> 0
A31: 31 | B31: Earthwork | C31: 0 | D31: 0 | E31: 0 | G31: =SUM(D31:F31) -> 0 | H31: =IFERROR(G31/C31,0) -> 0 | I31: =C31-G31 -> 0 | J31: =SUMIF(Detail!$E$4:$E$91,A31,Detail!$H$4:$H$91) -> 0
A32: 32 | B32: Exterior Improvements | C32: 0 | D32: 0 | E32: =SUMIFS(Detail!$G$3:$G$92,Detail!$D$3:$D$92,"01",Detail!$E$3:$E$92,'703'!A32) -> 0 | G32: =SUM(D32:F32) -> 0 | H32: =IFERROR(G32/C32,0) -> 0 | I32: =C32-G32 -> 0 | J32: =SUMIF(Detail!$E$4:$E$91,A32,Detail!$H$4:$H$91) -> 0
A33: 33 | B33: Utilities | C33: 0 | D33: 0 | E33: =SUMIFS(Detail!$G$3:$G$92,Detail!$D$3:$D$92,"01",Detail!$E$3:$E$92,'703'!A33) -> 0 | G33: =SUM(D33:F33) -> 0 | H33: =IFERROR(G33/C33,0) -> 0 | I33: =C33-G33 -> 0 | J33: =SUMIF(Detail!$E$4:$E$91,A33,Detail!$H$4:$H$91) -> 0
A34: HC | B34: Hard Cost Contingency | C34: 0 | D34: 0 | E34: =SUMIFS(Detail!$G$3:$G$92,Detail!$D$3:$D$92,"01",Detail!$E$3:$E$92,'703'!A34) -> 0 | G34: =SUM(D34:F34) -> 0 | H34: =IFERROR(G34/C34,0) -> 0 | I34: =C34-G34 -> 0 | J34: =SUMIF(Detail!$E$4:$E$91,A34,Detail!$H$4:$H$91) -> 0
B37: HARD COSTS SUBTOTAL | C37: =SUM(C12:C35) -> 0 | D37: =SUM(D11:D35) -> 0 | E37: =SUM(E11:E35) -> 0 | F37: =SUM(F11:F35) -> 0 | G37: =SUM(D37:F37) -> 0 | H37: =G37/(C37) -> #DIV/0! | I37: =C37-G37 -> 0 | J37: =SUM(J11:J35) -> 0
I38: =C38-G38 -> 0
B39: CONSTRUCTION SOFT COSTS | I39: =C39-G39 -> 0
A40: 60 | B40: Land Costs | C40: 0 | D40: 0 | E40: =SUMIFS(Detail!$G$3:$G$92,Detail!$D$3:$D$92,"01",Detail!$E$3:$E$92,'703'!A40) -> 0 | G40: =SUM(D40:F40) -> 0 | H40: =IFERROR(G40/C40,0) -> 0 | I40: =C40-G40 -> 0 | J40: =SUMIF(Detail!$E$4:$E$88,A40,Detail!$H$4:$H$88) -> 0
A41: 61 | B41: Development Services & Fees | C41: 0 | D41: 0 | E41: =SUMIFS(Detail!$G$3:$G$92,Detail!$D$3:$D$92,"01",Detail!$E$3:$E$92,'703'!A41) -> 0 | G41: =SUM(D41:E41) -> 0 | H41: =IFERROR(G41/C41,0) -> 0 | I41: =C41-G41 -> 0 | J41: =SUMIF(Detail!$E$4:$E$88,A41,Detail!$H$4:$H$88) -> 0
A42: 62 | B42: Architectural Design Fees | C42: 0 | D42: 0 | E42: =SUMIFS(Detail!$G$3:$G$92,Detail!$D$3:$D$92,"01",Detail!$E$3:$E$92,'703'!A42) -> 0 | G42: =SUM(D42:E42) -> 0 | H42: =IFERROR(G42/C42,0) -> 0 | I42: =C42-G42 -> 0 | J42: =SUMIF(Detail!$E$4:$E$88,A42,Detail!$H$4:$H$88) -> 0
A43: 63 | B43: Civil Engineering | C43: 0 | D43: 0 | E43: =SUMIFS(Detail!$G$3:$G$92,Detail!$D$3:$D$92,"01",Detail!$E$3:$E$92,'703'!A43) -> 0 | G43: =SUM(D43:E43) -> 0 | H43: =IFERROR(G43/C43,0) -> 0 | I43: =C43-G43 -> 0 | J43: =SUMIF(Detail!$E$4:$E$88,A43,Detail!$H$4:$H$88) -> 0
A44: 64 | B44: Preconstruction Services | C44: 0 | D44: 0 | E44: =SUMIFS(Detail!$G$3:$G$92,Detail!$D$3:$D$92,"01",Detail!$E$3:$E$92,'703'!A44) -> 0 | G44: =SUM(D44:E44) -> 0 | H44: =IFERROR(G44/C44,0) -> 0 | I44: =C44-G44 -> 0 | J44: =SUMIF(Detail!$E$4:$E$88,A44,Detail!$H$4:$H$88) -> 0
...

Sheet Detail
A2: Vendor | B2: Invoice | C2: Invoice Date | D2: Draw # | E2: AIA Item | F2: Cost Type | G2: Cost | H2: Retainage | I2: Total | J2: Invoice Copy? | K2: Check #/Wire # | L2: Date
I89: =G89-H89 -> 0
I90: =G90-H90 -> 0
F93: TOTAL | G93: =SUBTOTAL(109,G3:G92) -> 0 | H93: =SUBTOTAL(109,H3:H92) -> 0 | I93: =SUBTOTAL(109,I3:I92) -> 0

Sheet _REFERENCE888777888
A1: WorkSheet Name | B1: Report Code | C1: Company Id | D1: Job Id | E1: Start Date | F1: End Date | G1: Payroll Subledger | H1: Pay Period Id
